<?xml version="1.0"?>
<robot name="opticar">
  <material name="gray">
    <color rgba="0.6 0.6 0.6 1" />
  </material>
  <material name="lightgray">
    <color rgba="0.8 0.8 0.8 1" />
  </material>

  <link name="base_link">
    <visual>
      <geometry>
        <box size="1.1 0.53 0.38" />
      </geometry>
      <origin xyz="0.0 0.0 0.29" />
      <material name="gray" />
    </visual>
    <visual>
      <geometry>
        <box size="0.39 0.53 0.2" />
      </geometry>
      <origin xyz="0.1 0.0 0.58" />
      <material name="gray" />
    </visual>
    <collision>
      <geometry>
        <box size="1.1 0.53 0.38" />
      </geometry>
      <origin xyz="0.0 0.0 0.29" />
    </collision>
    <collision>
      <geometry>
        <box size="0.39 0.53 0.2" />
      </geometry>
      <origin xyz="0.1 0.0 0.58" />
    </collision>
    <inertial>
      <mass value="40" />
      <inertia ixx="1.42" ixy="0.0" ixz="0.0" iyy="4.51" iyz="0.0" izz="4.97" />
    </inertial>
  </link>

  <link name="wheel_front_left">
    <visual>
      <geometry>
        <cylinder length="0.095" radius="0.105" />
      </geometry>
      <origin rpy="1.57 0.0 0.0"/>
      <material name="lightgray" />
    </visual>
    <collision>
      <geometry>
        <cylinder length="0.095" radius="0.105" />
      </geometry>
      <origin rpy="1.57 0.0 0.0"/>
    </collision>
    <inertial>
      <mass value="1.6" />
      <inertia ixx="0.0057" ixy="0.0" ixz="0.0" iyy="0.0057" iyz="0.0" izz="0.0088" />
    </inertial>
  </link>
  <link name="wheel_front_right">
    <visual>
      <geometry>
        <cylinder length="0.095" radius="0.105" />
      </geometry>
      <origin rpy="1.57 0.0 0.0"/>
      <material name="lightgray" />
    </visual>
    <collision>
      <geometry>
        <cylinder length="0.095" radius="0.105" />
      </geometry>
      <origin rpy="1.57 0.0 0.0"/>
    </collision>
    <inertial>
      <mass value="1.6" />
      <inertia ixx="0.0057" ixy="0.0" ixz="0.0" iyy="0.0057" iyz="0.0" izz="0.0088" />
    </inertial>
  </link>
  <link name="wheel_rear_left">
    <visual>
      <geometry>
        <cylinder length="0.095" radius="0.105" />
      </geometry>
      <origin rpy="1.57 0.0 0.0"/>
      <material name="lightgray" />
    </visual>
    <collision>
      <geometry>
        <cylinder length="0.095" radius="0.105" />
      </geometry>
      <origin rpy="1.57 0.0 0.0"/>
    </collision>
    <inertial>
      <mass value="1.6" />
      <inertia ixx="0.0057" ixy="0.0" ixz="0.0" iyy="0.0057" iyz="0.0" izz="0.0088" />
    </inertial>
  </link>
  <link name="wheel_rear_right">
    <visual>
      <geometry>
        <cylinder length="0.095" radius="0.105" />
      </geometry>
      <origin rpy="1.57 0.0 0.0"/>
      <material name="lightgray" />
    </visual>
    <collision>
      <geometry>
        <cylinder length="0.095" radius="0.105" />
      </geometry>
      <origin rpy="1.57 0.0 0.0"/>
    </collision>
    <inertial>
      <mass value="1.6" />
      <inertia ixx="0.0057" ixy="0.0" ixz="0.0" iyy="0.0057" iyz="0.0" izz="0.0088" />
    </inertial>
  </link>

  <joint name="base_to_wheel_front_left" type="continuous">
    <parent link="base_link" />
    <child link="wheel_front_left" />
    <origin xyz="0.42 0.3125 0.105" />
    <axis xyz="0 1 0" />
  </joint>
  <joint name="base_to_wheel_front_right" type="continuous">
    <parent link="base_link" />
    <child link="wheel_front_right" />
    <origin xyz="0.42 -0.3125 0.105" />
    <axis xyz="0 1 0" />
  </joint>
  <joint name="base_to_wheel_rear_left" type="continuous">
    <parent link="base_link" />
    <child link="wheel_rear_left" />
    <origin xyz="-0.42 0.3125 0.105" />
    <axis xyz="0 1 0" />
  </joint>
  <joint name="base_to_wheel_rear_right" type="continuous">
    <parent link="base_link" />
    <child link="wheel_rear_right" />
    <origin xyz="-0.42 -0.3125 0.105" />
    <axis xyz="0 1 0" />
  </joint>
</robot>
